2022-12-27 11:54:57.631 | ERROR    | graia.ariadne.util:loguru_exc_callback:76 - Exception:
Traceback (most recent call last):

  File "F:\CODE\BfBot\bot-xiaomai-open\main.py", line 138, in <module>
    core.launch()
    │    └ <staticmethod object at 0x0000011EFC837520>
    └ <core.bot.Umaru object at 0x0000011EF81A8B50>

  File "F:\CODE\BfBot\bot-xiaomai-open\core\bot.py", line 282, in launch
    Ariadne.launch_blocking()
    │       └ <classmethod object at 0x0000011EFB4C6910>
    └ <class 'graia.ariadne.app.Ariadne'>

  File "F:\CODE\BfBot\bot-xiaomai-open\venv\lib\site-packages\graia\ariadne\app.py", line 303, in launch_blocking
    def launch_blocking(cls, stop_signals: Iterable[signal.Signals] = (signal.SIGINT,)):
                        │    │             │        │      │           │      └ <Signals.SIGINT: 2>
                        │    │             │        │      │           └ <module 'signal' from 'C:\\Users\\Gyc\\AppData\\Local\\Programs\\Python\\Python39\\lib\\signal.py'>
                        │    │             │        │      └ <enum 'Signals'>
                        │    │             │        └ <module 'signal' from 'C:\\Users\\Gyc\\AppData\\Local\\Programs\\Python\\Python39\\lib\\signal.py'>
                        │    │             └ typing.Iterable
                        │    └ (<Signals.SIGINT: 2>,)
                        └ <class 'graia.ariadne.app.Ariadne'>

  File "F:\CODE\BfBot\bot-xiaomai-open\venv\lib\site-packages\launart\manager.py", line 461, in launch_blocking
    loop.run_until_complete(launch_task)
    │    │                  └ <Task pending name='amnesia-launch' coro=<Launart.launch() running at F:\CODE\BfBot\bot-xiaomai-open\venv\lib\site-packages\l...
    │    └ <function BaseEventLoop.run_until_complete at 0x0000011EFA6B0DC0>
    └ <ProactorEventLoop running=True closed=False debug=False>

  File "C:\Users\Gyc\AppData\Local\Programs\Python\Python39\lib\asyncio\base_events.py", line 629, in run_until_complete
    self.run_forever()
    │    └ <function ProactorEventLoop.run_forever at 0x0000011EFA72D670>
    └ <ProactorEventLoop running=True closed=False debug=False>

  File "C:\Users\Gyc\AppData\Local\Programs\Python\Python39\lib\asyncio\windows_events.py", line 316, in run_forever
    super().run_forever()

  File "C:\Users\Gyc\AppData\Local\Programs\Python\Python39\lib\asyncio\base_events.py", line 596, in run_forever
    self._run_once()
    │    └ <function BaseEventLoop._run_once at 0x0000011EFA6B58B0>
    └ <ProactorEventLoop running=True closed=False debug=False>

  File "C:\Users\Gyc\AppData\Local\Programs\Python\Python39\lib\asyncio\base_events.py", line 1890, in _run_once
    handle._run()
    │      └ <function Handle._run at 0x0000011EFA64E4C0>
    └ <Handle <TaskWakeupMethWrapper object at 0x0000011EFDDFD310>(<_GatheringFu...e, None, ...]>)>

  File "C:\Users\Gyc\AppData\Local\Programs\Python\Python39\lib\asyncio\events.py", line 80, in _run
    self._context.run(self._callback, *self._args)
    │    │            │    │           │    └ <member '_args' of 'Handle' objects>
    │    │            │    │           └ <Handle <TaskWakeupMethWrapper object at 0x0000011EFDDFD310>(<_GatheringFu...e, None, ...]>)>
    │    │            │    └ <member '_callback' of 'Handle' objects>
    │    │            └ <Handle <TaskWakeupMethWrapper object at 0x0000011EFDDFD310>(<_GatheringFu...e, None, ...]>)>
    │    └ <member '_context' of 'Handle' objects>
    └ <Handle <TaskWakeupMethWrapper object at 0x0000011EFDDFD310>(<_GatheringFu...e, None, ...]>)>

> File "F:\CODE\BfBot\bot-xiaomai-open\venv\lib\site-packages\graia\broadcast\__init__.py", line 191, in Executor
    result = await run_always_await(target_callable, **parameter_compile_result)
                   │                │                  └ {'app': <graia.ariadne.app.Ariadne object at 0x0000011EFA871160>, 'group': Group(id=1090153034, name='bot测试群', account_perm=<...
                   │                └ <function help_manager at 0x0000011EFC92A820>
                   └ <function run_always_await at 0x0000011EFAA81820>

  File "F:\CODE\BfBot\bot-xiaomai-open\venv\lib\site-packages\graia\broadcast\utilles.py", line 34, in run_always_await
    obj = await obj
                └ <coroutine object help_manager at 0x0000011EFDDE86C0>

  File "F:\CODE\BfBot\bot-xiaomai-open\modules\required\perm_manager\__init__.py", line 447, in help_manager
    ), quote=message[Source][0])
             │       └ <class 'graia.ariadne.message.Source'>
             └ MessageChain([Plain(text='-help perm')])

  File "F:\CODE\BfBot\bot-xiaomai-open\venv\lib\site-packages\graia\ariadne\message\chain.py", line 181, in __getitem__
    return super().__getitem__(item)
                               └ <class 'graia.ariadne.message.Source'>

  File "F:\CODE\BfBot\bot-xiaomai-open\venv\lib\site-packages\graia\amnesia\message\__init__.py", line 196, in __getitem__
    raise NotImplementedError("{0} is not allowed for item getting".format(type(item)))
                                                                                └ <class 'graia.ariadne.message.Source'>

NotImplementedError: <class 'pydantic.main.ModelMetaclass'> is not allowed for item getting
2022-12-27 11:55:04.618 | ERROR    | graia.ariadne.util:loguru_exc_callback:76 - Exception:
Traceback (most recent call last):

  File "F:\CODE\BfBot\bot-xiaomai-open\main.py", line 138, in <module>
    core.launch()
    │    └ <staticmethod object at 0x0000011EFC837520>
    └ <core.bot.Umaru object at 0x0000011EF81A8B50>

  File "F:\CODE\BfBot\bot-xiaomai-open\core\bot.py", line 282, in launch
    Ariadne.launch_blocking()
    │       └ <classmethod object at 0x0000011EFB4C6910>
    └ <class 'graia.ariadne.app.Ariadne'>

  File "F:\CODE\BfBot\bot-xiaomai-open\venv\lib\site-packages\graia\ariadne\app.py", line 303, in launch_blocking
    def launch_blocking(cls, stop_signals: Iterable[signal.Signals] = (signal.SIGINT,)):
                        │    │             │        │      │           │      └ <Signals.SIGINT: 2>
                        │    │             │        │      │           └ <module 'signal' from 'C:\\Users\\Gyc\\AppData\\Local\\Programs\\Python\\Python39\\lib\\signal.py'>
                        │    │             │        │      └ <enum 'Signals'>
                        │    │             │        └ <module 'signal' from 'C:\\Users\\Gyc\\AppData\\Local\\Programs\\Python\\Python39\\lib\\signal.py'>
                        │    │             └ typing.Iterable
                        │    └ (<Signals.SIGINT: 2>,)
                        └ <class 'graia.ariadne.app.Ariadne'>

  File "F:\CODE\BfBot\bot-xiaomai-open\venv\lib\site-packages\launart\manager.py", line 461, in launch_blocking
    loop.run_until_complete(launch_task)
    │    │                  └ <Task pending name='amnesia-launch' coro=<Launart.launch() running at F:\CODE\BfBot\bot-xiaomai-open\venv\lib\site-packages\l...
    │    └ <function BaseEventLoop.run_until_complete at 0x0000011EFA6B0DC0>
    └ <ProactorEventLoop running=True closed=False debug=False>

  File "C:\Users\Gyc\AppData\Local\Programs\Python\Python39\lib\asyncio\base_events.py", line 629, in run_until_complete
    self.run_forever()
    │    └ <function ProactorEventLoop.run_forever at 0x0000011EFA72D670>
    └ <ProactorEventLoop running=True closed=False debug=False>

  File "C:\Users\Gyc\AppData\Local\Programs\Python\Python39\lib\asyncio\windows_events.py", line 316, in run_forever
    super().run_forever()

  File "C:\Users\Gyc\AppData\Local\Programs\Python\Python39\lib\asyncio\base_events.py", line 596, in run_forever
    self._run_once()
    │    └ <function BaseEventLoop._run_once at 0x0000011EFA6B58B0>
    └ <ProactorEventLoop running=True closed=False debug=False>

  File "C:\Users\Gyc\AppData\Local\Programs\Python\Python39\lib\asyncio\base_events.py", line 1890, in _run_once
    handle._run()
    │      └ <function Handle._run at 0x0000011EFA64E4C0>
    └ <Handle <TaskWakeupMethWrapper object at 0x0000011EFDDFD310>(<Future finished result=None>)>

  File "C:\Users\Gyc\AppData\Local\Programs\Python\Python39\lib\asyncio\events.py", line 80, in _run
    self._context.run(self._callback, *self._args)
    │    │            │    │           │    └ <member '_args' of 'Handle' objects>
    │    │            │    │           └ <Handle <TaskWakeupMethWrapper object at 0x0000011EFDDFD310>(<Future finished result=None>)>
    │    │            │    └ <member '_callback' of 'Handle' objects>
    │    │            └ <Handle <TaskWakeupMethWrapper object at 0x0000011EFDDFD310>(<Future finished result=None>)>
    │    └ <member '_context' of 'Handle' objects>
    └ <Handle <TaskWakeupMethWrapper object at 0x0000011EFDDFD310>(<Future finished result=None>)>

> File "F:\CODE\BfBot\bot-xiaomai-open\venv\lib\site-packages\graia\broadcast\__init__.py", line 191, in Executor
    result = await run_always_await(target_callable, **parameter_compile_result)
                   │                │                  └ {'app': <graia.ariadne.app.Ariadne object at 0x0000011EFA871160>, 'group': Group(id=1090153034, name='bot测试群', account_perm=<...
                   │                └ <function check_perm at 0x0000011EFC92A5E0>
                   └ <function run_always_await at 0x0000011EFAA81820>

  File "F:\CODE\BfBot\bot-xiaomai-open\venv\lib\site-packages\graia\broadcast\utilles.py", line 34, in run_always_await
    obj = await obj
                └ <coroutine object check_perm at 0x0000011EFDDE88C0>

  File "F:\CODE\BfBot\bot-xiaomai-open\modules\required\perm_manager\__init__.py", line 426, in check_perm
    ), quote=message[Source][0])
             │       └ <class 'graia.ariadne.message.Source'>
             └ MessageChain([Plain(text='-test perm')])

  File "F:\CODE\BfBot\bot-xiaomai-open\venv\lib\site-packages\graia\ariadne\message\chain.py", line 181, in __getitem__
    return super().__getitem__(item)
                               └ <class 'graia.ariadne.message.Source'>

  File "F:\CODE\BfBot\bot-xiaomai-open\venv\lib\site-packages\graia\amnesia\message\__init__.py", line 196, in __getitem__
    raise NotImplementedError("{0} is not allowed for item getting".format(type(item)))
                                                                                └ <class 'graia.ariadne.message.Source'>

NotImplementedError: <class 'pydantic.main.ModelMetaclass'> is not allowed for item getting
2022-12-27 11:55:26.348 | ERROR    | graia.ariadne.util:loguru_exc_callback:76 - Exception:
Traceback (most recent call last):

  File "F:\CODE\BfBot\bot-xiaomai-open\main.py", line 138, in <module>
    core.launch()
    │    └ <staticmethod object at 0x0000011EFC837520>
    └ <core.bot.Umaru object at 0x0000011EF81A8B50>

  File "F:\CODE\BfBot\bot-xiaomai-open\core\bot.py", line 282, in launch
    Ariadne.launch_blocking()
    │       └ <classmethod object at 0x0000011EFB4C6910>
    └ <class 'graia.ariadne.app.Ariadne'>

  File "F:\CODE\BfBot\bot-xiaomai-open\venv\lib\site-packages\graia\ariadne\app.py", line 303, in launch_blocking
    def launch_blocking(cls, stop_signals: Iterable[signal.Signals] = (signal.SIGINT,)):
                        │    │             │        │      │           │      └ <Signals.SIGINT: 2>
                        │    │             │        │      │           └ <module 'signal' from 'C:\\Users\\Gyc\\AppData\\Local\\Programs\\Python\\Python39\\lib\\signal.py'>
                        │    │             │        │      └ <enum 'Signals'>
                        │    │             │        └ <module 'signal' from 'C:\\Users\\Gyc\\AppData\\Local\\Programs\\Python\\Python39\\lib\\signal.py'>
                        │    │             └ typing.Iterable
                        │    └ (<Signals.SIGINT: 2>,)
                        └ <class 'graia.ariadne.app.Ariadne'>

  File "F:\CODE\BfBot\bot-xiaomai-open\venv\lib\site-packages\launart\manager.py", line 461, in launch_blocking
    loop.run_until_complete(launch_task)
    │    │                  └ <Task pending name='amnesia-launch' coro=<Launart.launch() running at F:\CODE\BfBot\bot-xiaomai-open\venv\lib\site-packages\l...
    │    └ <function BaseEventLoop.run_until_complete at 0x0000011EFA6B0DC0>
    └ <ProactorEventLoop running=True closed=False debug=False>

  File "C:\Users\Gyc\AppData\Local\Programs\Python\Python39\lib\asyncio\base_events.py", line 629, in run_until_complete
    self.run_forever()
    │    └ <function ProactorEventLoop.run_forever at 0x0000011EFA72D670>
    └ <ProactorEventLoop running=True closed=False debug=False>

  File "C:\Users\Gyc\AppData\Local\Programs\Python\Python39\lib\asyncio\windows_events.py", line 316, in run_forever
    super().run_forever()

  File "C:\Users\Gyc\AppData\Local\Programs\Python\Python39\lib\asyncio\base_events.py", line 596, in run_forever
    self._run_once()
    │    └ <function BaseEventLoop._run_once at 0x0000011EFA6B58B0>
    └ <ProactorEventLoop running=True closed=False debug=False>

  File "C:\Users\Gyc\AppData\Local\Programs\Python\Python39\lib\asyncio\base_events.py", line 1890, in _run_once
    handle._run()
    │      └ <function Handle._run at 0x0000011EFA64E4C0>
    └ <Handle <TaskWakeupMethWrapper object at 0x0000011EFDCEBD30>(<Future finished result=None>)>

  File "C:\Users\Gyc\AppData\Local\Programs\Python\Python39\lib\asyncio\events.py", line 80, in _run
    self._context.run(self._callback, *self._args)
    │    │            │    │           │    └ <member '_args' of 'Handle' objects>
    │    │            │    │           └ <Handle <TaskWakeupMethWrapper object at 0x0000011EFDCEBD30>(<Future finished result=None>)>
    │    │            │    └ <member '_callback' of 'Handle' objects>
    │    │            └ <Handle <TaskWakeupMethWrapper object at 0x0000011EFDCEBD30>(<Future finished result=None>)>
    │    └ <member '_context' of 'Handle' objects>
    └ <Handle <TaskWakeupMethWrapper object at 0x0000011EFDCEBD30>(<Future finished result=None>)>

> File "F:\CODE\BfBot\bot-xiaomai-open\venv\lib\site-packages\graia\broadcast\__init__.py", line 191, in Executor
    result = await run_always_await(target_callable, **parameter_compile_result)
                   │                │                  └ {'app': <graia.ariadne.app.Ariadne object at 0x0000011EFA871160>, 'group': Group(id=1090153034, name='bot测试群', account_perm=<...
                   │                └ <function check_perm at 0x0000011EFC92A5E0>
                   └ <function run_always_await at 0x0000011EFAA81820>

  File "F:\CODE\BfBot\bot-xiaomai-open\venv\lib\site-packages\graia\broadcast\utilles.py", line 34, in run_always_await
    obj = await obj
                └ <coroutine object check_perm at 0x0000011EFDE564C0>

  File "F:\CODE\BfBot\bot-xiaomai-open\modules\required\perm_manager\__init__.py", line 426, in check_perm
    ), quote=message[Source][0])
             │       └ <class 'graia.ariadne.message.Source'>
             └ MessageChain([Plain(text='-test perm')])

  File "F:\CODE\BfBot\bot-xiaomai-open\venv\lib\site-packages\graia\ariadne\message\chain.py", line 181, in __getitem__
    return super().__getitem__(item)
                               └ <class 'graia.ariadne.message.Source'>

  File "F:\CODE\BfBot\bot-xiaomai-open\venv\lib\site-packages\graia\amnesia\message\__init__.py", line 196, in __getitem__
    raise NotImplementedError("{0} is not allowed for item getting".format(type(item)))
                                                                                └ <class 'graia.ariadne.message.Source'>

NotImplementedError: <class 'pydantic.main.ModelMetaclass'> is not allowed for item getting
2022-12-27 11:58:52.108 | ERROR    | graia.ariadne.util:loguru_exc_callback:76 - Exception:
Traceback (most recent call last):

  File "F:\CODE\BfBot\bot-xiaomai-open\main.py", line 138, in <module>
    core.launch()
    │    └ <staticmethod object at 0x0000011EFC837520>
    └ <core.bot.Umaru object at 0x0000011EF81A8B50>

  File "F:\CODE\BfBot\bot-xiaomai-open\core\bot.py", line 282, in launch
    Ariadne.launch_blocking()
    │       └ <classmethod object at 0x0000011EFB4C6910>
    └ <class 'graia.ariadne.app.Ariadne'>

  File "F:\CODE\BfBot\bot-xiaomai-open\venv\lib\site-packages\graia\ariadne\app.py", line 303, in launch_blocking
    def launch_blocking(cls, stop_signals: Iterable[signal.Signals] = (signal.SIGINT,)):
                        │    │             │        │      │           │      └ <Signals.SIGINT: 2>
                        │    │             │        │      │           └ <module 'signal' from 'C:\\Users\\Gyc\\AppData\\Local\\Programs\\Python\\Python39\\lib\\signal.py'>
                        │    │             │        │      └ <enum 'Signals'>
                        │    │             │        └ <module 'signal' from 'C:\\Users\\Gyc\\AppData\\Local\\Programs\\Python\\Python39\\lib\\signal.py'>
                        │    │             └ typing.Iterable
                        │    └ (<Signals.SIGINT: 2>,)
                        └ <class 'graia.ariadne.app.Ariadne'>

  File "F:\CODE\BfBot\bot-xiaomai-open\venv\lib\site-packages\launart\manager.py", line 461, in launch_blocking
    loop.run_until_complete(launch_task)
    │    │                  └ <Task pending name='amnesia-launch' coro=<Launart.launch() running at F:\CODE\BfBot\bot-xiaomai-open\venv\lib\site-packages\l...
    │    └ <function BaseEventLoop.run_until_complete at 0x0000011EFA6B0DC0>
    └ <ProactorEventLoop running=True closed=False debug=False>

  File "C:\Users\Gyc\AppData\Local\Programs\Python\Python39\lib\asyncio\base_events.py", line 629, in run_until_complete
    self.run_forever()
    │    └ <function ProactorEventLoop.run_forever at 0x0000011EFA72D670>
    └ <ProactorEventLoop running=True closed=False debug=False>

  File "C:\Users\Gyc\AppData\Local\Programs\Python\Python39\lib\asyncio\windows_events.py", line 316, in run_forever
    super().run_forever()

  File "C:\Users\Gyc\AppData\Local\Programs\Python\Python39\lib\asyncio\base_events.py", line 596, in run_forever
    self._run_once()
    │    └ <function BaseEventLoop._run_once at 0x0000011EFA6B58B0>
    └ <ProactorEventLoop running=True closed=False debug=False>

  File "C:\Users\Gyc\AppData\Local\Programs\Python\Python39\lib\asyncio\base_events.py", line 1890, in _run_once
    handle._run()
    │      └ <function Handle._run at 0x0000011EFA64E4C0>
    └ <Handle <TaskWakeupMethWrapper object at 0x0000011EFDCDA430>(<Future finished result=None>)>

  File "C:\Users\Gyc\AppData\Local\Programs\Python\Python39\lib\asyncio\events.py", line 80, in _run
    self._context.run(self._callback, *self._args)
    │    │            │    │           │    └ <member '_args' of 'Handle' objects>
    │    │            │    │           └ <Handle <TaskWakeupMethWrapper object at 0x0000011EFDCDA430>(<Future finished result=None>)>
    │    │            │    └ <member '_callback' of 'Handle' objects>
    │    │            └ <Handle <TaskWakeupMethWrapper object at 0x0000011EFDCDA430>(<Future finished result=None>)>
    │    └ <member '_context' of 'Handle' objects>
    └ <Handle <TaskWakeupMethWrapper object at 0x0000011EFDCDA430>(<Future finished result=None>)>

> File "F:\CODE\BfBot\bot-xiaomai-open\venv\lib\site-packages\graia\broadcast\__init__.py", line 191, in Executor
    result = await run_always_await(target_callable, **parameter_compile_result)
                   │                │                  └ {'app': <graia.ariadne.app.Ariadne object at 0x0000011EFA871160>, 'group': Group(id=1090153034, name='bot测试群', account_perm=<...
                   │                └ <function check_perm at 0x0000011EFC92A5E0>
                   └ <function run_always_await at 0x0000011EFAA81820>

  File "F:\CODE\BfBot\bot-xiaomai-open\venv\lib\site-packages\graia\broadcast\utilles.py", line 34, in run_always_await
    obj = await obj
                └ <coroutine object check_perm at 0x0000011EFDD9BBC0>

  File "F:\CODE\BfBot\bot-xiaomai-open\modules\required\perm_manager\__init__.py", line 426, in check_perm
    ), quote=message[Source][0])
             │       └ <class 'graia.ariadne.message.Source'>
             └ MessageChain([Plain(text='-test perm')])

  File "F:\CODE\BfBot\bot-xiaomai-open\venv\lib\site-packages\graia\ariadne\message\chain.py", line 181, in __getitem__
    return super().__getitem__(item)
                               └ <class 'graia.ariadne.message.Source'>

  File "F:\CODE\BfBot\bot-xiaomai-open\venv\lib\site-packages\graia\amnesia\message\__init__.py", line 196, in __getitem__
    raise NotImplementedError("{0} is not allowed for item getting".format(type(item)))
                                                                                └ <class 'graia.ariadne.message.Source'>

NotImplementedError: <class 'pydantic.main.ModelMetaclass'> is not allowed for item getting
2022-12-27 17:52:31.423 | ERROR    | graia.ariadne.util:loguru_exc_callback_async:123 - Exception in callback AiohttpClientConnectionRider.connection_manage.<locals>.<lambda>(<Task cancell...ion\ws.py:73>>) at F:\CODE\BfBot\bot-xiaomai-open\venv\lib\site-packages\graia\amnesia\builtins\aiohttp.py:244
handle: <Handle AiohttpClientConnectionRider.connection_manage.<locals>.<lambda>(<Task cancell...ion\ws.py:73>>) at F:\CODE\BfBot\bot-xiaomai-open\venv\lib\site-packages\graia\amnesia\builtins\aiohttp.py:244>
Traceback (most recent call last):

  File "F:\CODE\BfBot\bot-xiaomai-open\venv\lib\site-packages\graia\ariadne\connection\ws.py", line 76, in _
    await asyncio.sleep(5)
          │       └ <function sleep at 0x000001FF55340DC0>
          └ <module 'asyncio' from 'C:\\Users\\Gyc\\AppData\\Local\\Programs\\Python\\Python39\\lib\\asyncio\\__init__.py'>

  File "C:\Users\Gyc\AppData\Local\Programs\Python\Python39\lib\asyncio\tasks.py", line 651, in sleep
    return await future
                 └ <Future cancelled>

asyncio.exceptions.CancelledError


During handling of the above exception, another exception occurred:


Traceback (most recent call last):

  File "F:\CODE\BfBot\bot-xiaomai-open\main.py", line 138, in <module>
    core.launch()
    │    └ <staticmethod object at 0x000001FF574C5CD0>
    └ <core.bot.Umaru object at 0x000001FF52C40D90>

  File "F:\CODE\BfBot\bot-xiaomai-open\core\bot.py", line 282, in launch
    Ariadne.launch_blocking()
    │       └ <classmethod object at 0x000001FF56962400>
    └ <class 'graia.ariadne.app.Ariadne'>

  File "F:\CODE\BfBot\bot-xiaomai-open\venv\lib\site-packages\graia\ariadne\app.py", line 313, in launch_blocking
    cls.launch_manager.launch_blocking(loop=cls.service.loop, stop_signal=stop_signals)
    │   │              │                    │   │       │                 └ (<Signals.SIGINT: 2>,)
    │   │              │                    │   │       └ <property object at 0x000001FF569569A0>
    │   │              │                    │   └ <graia.ariadne.service.ElizabethService object at 0x000001FF55550220>
    │   │              │                    └ <class 'graia.ariadne.app.Ariadne'>
    │   │              └ <function Launart.launch_blocking at 0x000001FF556E25E0>
    │   └ <launart.manager.Launart object at 0x000001FF574DC490>
    └ <class 'graia.ariadne.app.Ariadne'>

  File "F:\CODE\BfBot\bot-xiaomai-open\venv\lib\site-packages\launart\manager.py", line 468, in launch_blocking
    self._cancel_tasks(loop)
    │    │             └ <ProactorEventLoop running=True closed=False debug=False>
    │    └ <staticmethod object at 0x000001FF556E0250>
    └ <launart.manager.Launart object at 0x000001FF574DC490>

  File "F:\CODE\BfBot\bot-xiaomai-open\venv\lib\site-packages\launart\manager.py", line 497, in _cancel_tasks
    loop.run_until_complete(asyncio.gather(*to_cancel, return_exceptions=True))
    │    │                  │       │       └ {<Task cancelled name='Task-35' coro=<WebsocketConnectionMixin._() done, defined at F:\CODE\BfBot\bot-xiaomai-open\venv\lib\s...
    │    │                  │       └ <function gather at 0x000001FF55340F70>
    │    │                  └ <module 'asyncio' from 'C:\\Users\\Gyc\\AppData\\Local\\Programs\\Python\\Python39\\lib\\asyncio\\__init__.py'>
    │    └ <function BaseEventLoop.run_until_complete at 0x000001FF5534CB80>
    └ <ProactorEventLoop running=True closed=False debug=False>

  File "C:\Users\Gyc\AppData\Local\Programs\Python\Python39\lib\asyncio\base_events.py", line 629, in run_until_complete
    self.run_forever()
    │    └ <function ProactorEventLoop.run_forever at 0x000001FF553CD430>
    └ <ProactorEventLoop running=True closed=False debug=False>

  File "C:\Users\Gyc\AppData\Local\Programs\Python\Python39\lib\asyncio\windows_events.py", line 316, in run_forever
    super().run_forever()

  File "C:\Users\Gyc\AppData\Local\Programs\Python\Python39\lib\asyncio\base_events.py", line 596, in run_forever
    self._run_once()
    │    └ <function BaseEventLoop._run_once at 0x000001FF55350670>
    └ <ProactorEventLoop running=True closed=False debug=False>

  File "C:\Users\Gyc\AppData\Local\Programs\Python\Python39\lib\asyncio\base_events.py", line 1890, in _run_once
    handle._run()
    │      └ <function Handle._run at 0x000001FF552EC280>
    └ <Handle AiohttpClientConnectionRider.connection_manage.<locals>.<lambda>(<Task cancell...ion\ws.py:73>>) at F:\CODE\BfBot\bot...

> File "C:\Users\Gyc\AppData\Local\Programs\Python\Python39\lib\asyncio\events.py", line 80, in _run
    self._context.run(self._callback, *self._args)
    │    │            │    │           │    └ <member '_args' of 'Handle' objects>
    │    │            │    │           └ <Handle AiohttpClientConnectionRider.connection_manage.<locals>.<lambda>(<Task cancell...ion\ws.py:73>>) at F:\CODE\BfBot\bot...
    │    │            │    └ <member '_callback' of 'Handle' objects>
    │    │            └ <Handle AiohttpClientConnectionRider.connection_manage.<locals>.<lambda>(<Task cancell...ion\ws.py:73>>) at F:\CODE\BfBot\bot...
    │    └ <member '_context' of 'Handle' objects>
    └ <Handle AiohttpClientConnectionRider.connection_manage.<locals>.<lambda>(<Task cancell...ion\ws.py:73>>) at F:\CODE\BfBot\bot...

  File "F:\CODE\BfBot\bot-xiaomai-open\venv\lib\site-packages\graia\amnesia\builtins\aiohttp.py", line 244, in <lambda>
    lambda tsk: self.transports.append(t) if tsk.result() is True else None
           │    │    │          │      │     │   └ <method 'result' of '_asyncio.Task' objects>
           │    │    │          │      │     └ <Task cancelled name='Task-35' coro=<WebsocketConnectionMixin._() done, defined at F:\CODE\BfBot\bot-xiaomai-open\venv\lib\si...
           │    │    │          │      └ <WebsocketClientConnection <ConnectionStatus connected=False alive=False verified=False stage=blocking-completed> with 2 call...
           │    │    │          └ <method 'append' of 'list' objects>
           │    │    └ []
           │    └ <graia.amnesia.builtins.aiohttp.AiohttpClientConnectionRider object at 0x000001FF587B4520>
           └ <Task cancelled name='Task-35' coro=<WebsocketConnectionMixin._() done, defined at F:\CODE\BfBot\bot-xiaomai-open\venv\lib\si...

asyncio.exceptions.CancelledError
2022-12-27 17:52:58.208 | ERROR    | graia.ariadne.util:loguru_exc_callback_async:123 - Exception in callback AiohttpClientConnectionRider.connection_manage.<locals>.<lambda>(<Task cancell...ion\ws.py:73>>) at F:\CODE\BfBot\bot-xiaomai-open\venv\lib\site-packages\graia\amnesia\builtins\aiohttp.py:244
handle: <Handle AiohttpClientConnectionRider.connection_manage.<locals>.<lambda>(<Task cancell...ion\ws.py:73>>) at F:\CODE\BfBot\bot-xiaomai-open\venv\lib\site-packages\graia\amnesia\builtins\aiohttp.py:244>
Traceback (most recent call last):

  File "F:\CODE\BfBot\bot-xiaomai-open\venv\lib\site-packages\graia\ariadne\connection\ws.py", line 76, in _
    await asyncio.sleep(5)
          │       └ <function sleep at 0x0000016BB2C40DC0>
          └ <module 'asyncio' from 'C:\\Users\\Gyc\\AppData\\Local\\Programs\\Python\\Python39\\lib\\asyncio\\__init__.py'>

  File "C:\Users\Gyc\AppData\Local\Programs\Python\Python39\lib\asyncio\tasks.py", line 651, in sleep
    return await future
                 └ <Future cancelled>

asyncio.exceptions.CancelledError


During handling of the above exception, another exception occurred:


Traceback (most recent call last):

  File "F:\CODE\BfBot\bot-xiaomai-open\main.py", line 138, in <module>
    core.launch()
    │    └ <staticmethod object at 0x0000016BB4DC59A0>
    └ <core.bot.Umaru object at 0x0000016BB0550D90>

  File "F:\CODE\BfBot\bot-xiaomai-open\core\bot.py", line 282, in launch
    Ariadne.launch_blocking()
    │       └ <classmethod object at 0x0000016BB3A623D0>
    └ <class 'graia.ariadne.app.Ariadne'>

  File "F:\CODE\BfBot\bot-xiaomai-open\venv\lib\site-packages\graia\ariadne\app.py", line 313, in launch_blocking
    cls.launch_manager.launch_blocking(loop=cls.service.loop, stop_signal=stop_signals)
    │   │              │                    │   │       │                 └ (<Signals.SIGINT: 2>,)
    │   │              │                    │   │       └ <property object at 0x0000016BB3A56B30>
    │   │              │                    │   └ <graia.ariadne.service.ElizabethService object at 0x0000016BB2E60220>
    │   │              │                    └ <class 'graia.ariadne.app.Ariadne'>
    │   │              └ <function Launart.launch_blocking at 0x0000016BB2FE35E0>
    │   └ <launart.manager.Launart object at 0x0000016BB4DDC460>
    └ <class 'graia.ariadne.app.Ariadne'>

  File "F:\CODE\BfBot\bot-xiaomai-open\venv\lib\site-packages\launart\manager.py", line 468, in launch_blocking
    self._cancel_tasks(loop)
    │    │             └ <ProactorEventLoop running=True closed=False debug=False>
    │    └ <staticmethod object at 0x0000016BB2FE0250>
    └ <launart.manager.Launart object at 0x0000016BB4DDC460>

  File "F:\CODE\BfBot\bot-xiaomai-open\venv\lib\site-packages\launart\manager.py", line 497, in _cancel_tasks
    loop.run_until_complete(asyncio.gather(*to_cancel, return_exceptions=True))
    │    │                  │       │       └ {<Task cancelled name='Task-45' coro=<WebsocketConnectionMixin._() done, defined at F:\CODE\BfBot\bot-xiaomai-open\venv\lib\s...
    │    │                  │       └ <function gather at 0x0000016BB2C40F70>
    │    │                  └ <module 'asyncio' from 'C:\\Users\\Gyc\\AppData\\Local\\Programs\\Python\\Python39\\lib\\asyncio\\__init__.py'>
    │    └ <function BaseEventLoop.run_until_complete at 0x0000016BB2C4CB80>
    └ <ProactorEventLoop running=True closed=False debug=False>

  File "C:\Users\Gyc\AppData\Local\Programs\Python\Python39\lib\asyncio\base_events.py", line 629, in run_until_complete
    self.run_forever()
    │    └ <function ProactorEventLoop.run_forever at 0x0000016BB2CCD430>
    └ <ProactorEventLoop running=True closed=False debug=False>

  File "C:\Users\Gyc\AppData\Local\Programs\Python\Python39\lib\asyncio\windows_events.py", line 316, in run_forever
    super().run_forever()

  File "C:\Users\Gyc\AppData\Local\Programs\Python\Python39\lib\asyncio\base_events.py", line 596, in run_forever
    self._run_once()
    │    └ <function BaseEventLoop._run_once at 0x0000016BB2C50670>
    └ <ProactorEventLoop running=True closed=False debug=False>

  File "C:\Users\Gyc\AppData\Local\Programs\Python\Python39\lib\asyncio\base_events.py", line 1890, in _run_once
    handle._run()
    │      └ <function Handle._run at 0x0000016BB2BEC280>
    └ <Handle AiohttpClientConnectionRider.connection_manage.<locals>.<lambda>(<Task cancell...ion\ws.py:73>>) at F:\CODE\BfBot\bot...

> File "C:\Users\Gyc\AppData\Local\Programs\Python\Python39\lib\asyncio\events.py", line 80, in _run
    self._context.run(self._callback, *self._args)
    │    │            │    │           │    └ <member '_args' of 'Handle' objects>
    │    │            │    │           └ <Handle AiohttpClientConnectionRider.connection_manage.<locals>.<lambda>(<Task cancell...ion\ws.py:73>>) at F:\CODE\BfBot\bot...
    │    │            │    └ <member '_callback' of 'Handle' objects>
    │    │            └ <Handle AiohttpClientConnectionRider.connection_manage.<locals>.<lambda>(<Task cancell...ion\ws.py:73>>) at F:\CODE\BfBot\bot...
    │    └ <member '_context' of 'Handle' objects>
    └ <Handle AiohttpClientConnectionRider.connection_manage.<locals>.<lambda>(<Task cancell...ion\ws.py:73>>) at F:\CODE\BfBot\bot...

  File "F:\CODE\BfBot\bot-xiaomai-open\venv\lib\site-packages\graia\amnesia\builtins\aiohttp.py", line 244, in <lambda>
    lambda tsk: self.transports.append(t) if tsk.result() is True else None
           │    │    │          │      │     │   └ <method 'result' of '_asyncio.Task' objects>
           │    │    │          │      │     └ <Task cancelled name='Task-45' coro=<WebsocketConnectionMixin._() done, defined at F:\CODE\BfBot\bot-xiaomai-open\venv\lib\si...
           │    │    │          │      └ <WebsocketClientConnection <ConnectionStatus connected=False alive=False verified=False stage=blocking-completed> with 2 call...
           │    │    │          └ <method 'append' of 'list' objects>
           │    │    └ []
           │    └ <graia.amnesia.builtins.aiohttp.AiohttpClientConnectionRider object at 0x0000016BB60C64F0>
           └ <Task cancelled name='Task-45' coro=<WebsocketConnectionMixin._() done, defined at F:\CODE\BfBot\bot-xiaomai-open\venv\lib\si...

asyncio.exceptions.CancelledError
